Switching from python to 3/3.9.11
  ERROR: Unable to locate a modulefile for '3/3.9.11'
2023-10-04 02:06:45.338888: W tensorflow/compiler/tf2tensorrt/utils/py_utils.cc:38] TF-TRT Warning: Could not find TensorRT
No GPU/TPU found, falling back to CPU. (Set TF_CPP_MIN_LOG_LEVEL=0 and rerun for more info.)
2023-10-04 02:08:20.755282: W tensorflow/core/common_runtime/gpu/gpu_device.cc:1960] Cannot dlopen some GPU libraries. Please make sure the missing libraries mentioned above are installed properly if you would like to use GPU. Follow the guide at https://www.tensorflow.org/install/gpu for how to download and setup the required libraries for your platform.
Skipping registering GPU devices...
/zhome/77/8/118225/.local/lib/python3.8/site-packages/numpy/core/getlimits.py:518: UserWarning: The value of the smallest subnormal for <class 'numpy.float32'> type is zero.
  setattr(self, word, getattr(machar, word).flat[0])
/zhome/77/8/118225/.local/lib/python3.8/site-packages/numpy/core/getlimits.py:89: UserWarning: The value of the smallest subnormal for <class 'numpy.float32'> type is zero.
  return self._float_to_str(self.smallest_subnormal)
Traceback (most recent call last):
  File "train_score.py", line 670, in <module>
    trainxt(manifold=args.manifold,
  File "train_score.py", line 647, in trainxt
    score_matching.trainxt.train_s1(M=M,
  File "/zhome/77/8/118225/Desktop/smrdm/smrdm/jaxgeometry/statistics/score_matching/trainxt.py", line 144, in train_s1
    state, loss_val = update(state, next(train_dataset))
  File "/zhome/77/8/118225/.local/lib/python3.8/site-packages/tensorflow_datasets/core/dataset_utils.py", line 76, in _eager_dataset_iterator
    for elem in ds:
  File "/zhome/77/8/118225/.local/lib/python3.8/site-packages/tensorflow/python/data/ops/iterator_ops.py", line 814, in __next__
    return self._next_internal()
  File "/zhome/77/8/118225/.local/lib/python3.8/site-packages/tensorflow/python/data/ops/iterator_ops.py", line 777, in _next_internal
    ret = gen_dataset_ops.iterator_get_next(
  File "/zhome/77/8/118225/.local/lib/python3.8/site-packages/tensorflow/python/ops/gen_dataset_ops.py", line 3023, in iterator_get_next
    _result = pywrap_tfe.TFE_Py_FastPathExecute(
KeyboardInterrupt
terminate called without an active exception
/zhome/77/8/118225/.lsbatch/1696248248.17937723.shell: line 34: 25988 Aborted                 python3 train_score.py --manifold SN --N 5 --loss_type vsm --train_net s1 --max_T 1.0 --lr_rate 0.001 --epochs 50000 --x_samples 32 --t_samples 128 --repeats 8 --samples_per_batch 16 --dt_steps 1000 --save_step 10 --seed 2712
