Loaded dependency [python3/3.10.12]: gcc/11.4.0-binutils-2.40
Loaded dependency [python3/3.10.12]: sqlite3/3.42.0

Switching from python3/3.8.2 to python3/3.10.12
  Loading requirement: gcc/11.4.0-binutils-2.40 sqlite3/3.42.0
2024-02-21 16:52:30.036124: E tensorflow/compiler/xla/stream_executor/cuda/cuda_dnn.cc:9342] Unable to register cuDNN factory: Attempting to register factory for plugin cuDNN when one has already been registered
2024-02-21 16:52:30.036223: E tensorflow/compiler/xla/stream_executor/cuda/cuda_fft.cc:609] Unable to register cuFFT factory: Attempting to register factory for plugin cuFFT when one has already been registered
2024-02-21 16:52:30.044842: E tensorflow/compiler/xla/stream_executor/cuda/cuda_blas.cc:1518] Unable to register cuBLAS factory: Attempting to register factory for plugin cuBLAS when one has already been registered
/zhome/77/8/118225/.local/lib/python3.10/site-packages/numpy/core/getlimits.py:518: UserWarning: The value of the smallest subnormal for <class 'numpy.float32'> type is zero.
  setattr(self, word, getattr(machar, word).flat[0])
/zhome/77/8/118225/.local/lib/python3.10/site-packages/numpy/core/getlimits.py:89: UserWarning: The value of the smallest subnormal for <class 'numpy.float32'> type is zero.
  return self._float_to_str(self.smallest_subnormal)
jax.errors.SimplifiedTraceback: For simplicity, JAX has removed its internal frames from the traceback of the following exception. Set JAX_TRACEBACK_FILTERING=off to include these.

The above exception was the direct cause of the following exception:

Traceback (most recent call last):
  File "/zhome/77/8/118225/Desktop/Projects/score_diffusion_mean/score_diffusion_mean/train_score.py", line 545, in <module>
    train_score()
  File "/zhome/77/8/118225/Desktop/Projects/score_diffusion_mean/score_diffusion_mean/train_score.py", line 475, in train_score
    train_s2(M=M,
  File "/zhome/77/8/118225/Desktop/Projects/score_diffusion_mean/score_diffusion_mean/jaxgeometry/statistics/score_matching/trainxt.py", line 332, in train_s2
    state, loss_val = update(state, data)
  File "/zhome/77/8/118225/Desktop/Projects/score_diffusion_mean/score_diffusion_mean/jaxgeometry/statistics/score_matching/trainxt.py", line 295, in update
    loss, gradients = value_and_grad(loss_fun)(state.params, state.state_val, rng_key, data)
  File "/zhome/77/8/118225/Desktop/Projects/score_diffusion_mean/score_diffusion_mean/jaxgeometry/statistics/score_matching/trainxt.py", line 285, in loss_fun
    loss = jnp.mean(vmap(
  File "/zhome/77/8/118225/Desktop/Projects/score_diffusion_mean/score_diffusion_mean/jaxgeometry/statistics/score_matching/trainxt.py", line 229, in f
    loss3 = 2.*diff(psip-psi)#2*diff*((psip-psi)+(psim-psi))
TypeError: 'BatchTracer' object is not callable
2024-02-21 16:53:12.006892: W tensorflow/core/kernels/data/generator_dataset_op.cc:108] Error occurred when finalizing GeneratorDataset iterator: FAILED_PRECONDITION: Python interpreter state is not initialized. The process may be terminated.
	 [[{{node PyFunc}}]]
