Loaded dependency [python3/3.10.12]: gcc/11.4.0-binutils-2.40
Loaded dependency [python3/3.10.12]: sqlite3/3.42.0

Switching from python3/3.8.2 to python3/3.10.12
  Loading requirement: gcc/11.4.0-binutils-2.40 sqlite3/3.42.0
2024-03-19 13:19:42.053052: E tensorflow/compiler/xla/stream_executor/cuda/cuda_dnn.cc:9342] Unable to register cuDNN factory: Attempting to register factory for plugin cuDNN when one has already been registered
2024-03-19 13:19:42.053128: E tensorflow/compiler/xla/stream_executor/cuda/cuda_fft.cc:609] Unable to register cuFFT factory: Attempting to register factory for plugin cuFFT when one has already been registered
2024-03-19 13:19:42.060494: E tensorflow/compiler/xla/stream_executor/cuda/cuda_blas.cc:1518] Unable to register cuBLAS factory: Attempting to register factory for plugin cuBLAS when one has already been registered
2024-03-19 13:20:10.959746: W external/xla/xla/service/gpu/runtime/support.cc:58] Intercepted XLA runtime error:
UNKNOWN: cuSolver execution failed
2024-03-19 13:20:10.960607: E external/xla/xla/pjrt/pjrt_stream_executor_client.cc:2593] Execution of replica 0 failed: INTERNAL: Failed to execute XLA Runtime executable: run time error: custom call 'xla.gpu.cholesky' failed: cuSolver execution failed; current tracing scope: custom-call.6; current profiling annotation: XlaModule:#hlo_module=jit__lambda_,program_id=150#.
2024-03-19 13:20:11.050727: W tensorflow/core/framework/op_kernel.cc:1827] UNKNOWN: XlaRuntimeError: INTERNAL: Failed to execute XLA Runtime executable: run time error: custom call 'xla.gpu.cholesky' failed: cuSolver execution failed; current tracing scope: custom-call.6; current profiling annotation: XlaModule:#hlo_module=jit__lambda_,program_id=150#.
jax.errors.SimplifiedTraceback: For simplicity, JAX has removed its internal frames from the traceback of the following exception. Set JAX_TRACEBACK_FILTERING=off to include these.


The above exception was the direct cause of the following exception:


Traceback (most recent call last):

  File "/zhome/77/8/118225/.local/lib/python3.10/site-packages/tensorflow/python/ops/script_ops.py", line 270, in __call__
    ret = func(*args)

  File "/zhome/77/8/118225/.local/lib/python3.10/site-packages/tensorflow/python/autograph/impl/api.py", line 643, in wrapper
    return func(*args, **kwargs)

  File "/zhome/77/8/118225/.local/lib/python3.10/site-packages/tensorflow/python/data/ops/from_generator_op.py", line 198, in generator_py_func
    values = next(generator_state.get_iterator(iterator_id))

  File "/zhome/77/8/118225/Desktop/Projects/score_diffusion_mean/score_diffusion_mean/jaxgeometry/statistics/score_matching/generators.py", line 88, in __call__
    (ts,xss,chartss,*_) = self.product((jnp.repeat(self.x0s[0],self.x_samples,axis=0),

jaxlib.xla_extension.XlaRuntimeError: INTERNAL: Failed to execute XLA Runtime executable: run time error: custom call 'xla.gpu.cholesky' failed: cuSolver execution failed; current tracing scope: custom-call.6; current profiling annotation: XlaModule:#hlo_module=jit__lambda_,program_id=150#.


Traceback (most recent call last):
  File "/zhome/77/8/118225/Desktop/Projects/score_diffusion_mean/score_diffusion_mean/train_score.py", line 298, in <module>
    train_score()
  File "/zhome/77/8/118225/Desktop/Projects/score_diffusion_mean/score_diffusion_mean/train_score.py", line 276, in train_score
    train_s1(M=M,
  File "/zhome/77/8/118225/Desktop/Projects/score_diffusion_mean/score_diffusion_mean/jaxgeometry/statistics/score_matching/trainxt.py", line 95, in train_s1
    initial_params = model.init(jrandom.PRNGKey(seed), next(train_dataset)[:,:(2*N_dim+1)])
  File "/zhome/77/8/118225/.local/lib/python3.10/site-packages/tensorflow_datasets/core/dataset_utils.py", line 82, in _eager_dataset_iterator
    for elem in ds:
  File "/zhome/77/8/118225/.local/lib/python3.10/site-packages/tensorflow/python/data/ops/iterator_ops.py", line 809, in __next__
    return self._next_internal()
  File "/zhome/77/8/118225/.local/lib/python3.10/site-packages/tensorflow/python/data/ops/iterator_ops.py", line 772, in _next_internal
    ret = gen_dataset_ops.iterator_get_next(
  File "/zhome/77/8/118225/.local/lib/python3.10/site-packages/tensorflow/python/ops/gen_dataset_ops.py", line 3028, in iterator_get_next
    _ops.raise_from_not_ok_status(e, name)
  File "/zhome/77/8/118225/.local/lib/python3.10/site-packages/tensorflow/python/framework/ops.py", line 5888, in raise_from_not_ok_status
    raise core._status_to_exception(e) from None  # pylint: disable=protected-access
tensorflow.python.framework.errors_impl.UnknownError: {{function_node __wrapped__IteratorGetNext_output_types_1_device_/job:localhost/replica:0/task:0/device:CPU:0}} XlaRuntimeError: INTERNAL: Failed to execute XLA Runtime executable: run time error: custom call 'xla.gpu.cholesky' failed: cuSolver execution failed; current tracing scope: custom-call.6; current profiling annotation: XlaModule:#hlo_module=jit__lambda_,program_id=150#.
jax.errors.SimplifiedTraceback: For simplicity, JAX has removed its internal frames from the traceback of the following exception. Set JAX_TRACEBACK_FILTERING=off to include these.


The above exception was the direct cause of the following exception:


Traceback (most recent call last):

  File "/zhome/77/8/118225/.local/lib/python3.10/site-packages/tensorflow/python/ops/script_ops.py", line 270, in __call__
    ret = func(*args)

  File "/zhome/77/8/118225/.local/lib/python3.10/site-packages/tensorflow/python/autograph/impl/api.py", line 643, in wrapper
    return func(*args, **kwargs)

  File "/zhome/77/8/118225/.local/lib/python3.10/site-packages/tensorflow/python/data/ops/from_generator_op.py", line 198, in generator_py_func
    values = next(generator_state.get_iterator(iterator_id))

  File "/zhome/77/8/118225/Desktop/Projects/score_diffusion_mean/score_diffusion_mean/jaxgeometry/statistics/score_matching/generators.py", line 88, in __call__
    (ts,xss,chartss,*_) = self.product((jnp.repeat(self.x0s[0],self.x_samples,axis=0),

jaxlib.xla_extension.XlaRuntimeError: INTERNAL: Failed to execute XLA Runtime executable: run time error: custom call 'xla.gpu.cholesky' failed: cuSolver execution failed; current tracing scope: custom-call.6; current profiling annotation: XlaModule:#hlo_module=jit__lambda_,program_id=150#.


	 [[{{node PyFunc}}]] [Op:IteratorGetNext] name: 
2024-03-19 13:20:11.512918: E external/xla/xla/stream_executor/cuda/cuda_driver.cc:674] failed to unload module 0x38e8760; leaking: CUDA_ERROR_ILLEGAL_ADDRESS: an illegal memory access was encountered
2024-03-19 13:20:11.513971: E external/xla/xla/stream_executor/cuda/cuda_driver.cc:674] failed to unload module 0x7f562cd56310; leaking: CUDA_ERROR_ILLEGAL_ADDRESS: an illegal memory access was encountered
2024-03-19 13:20:11.515852: E external/xla/xla/stream_executor/cuda/cuda_driver.cc:674] failed to unload module 0x9760900; leaking: CUDA_ERROR_ILLEGAL_ADDRESS: an illegal memory access was encountered
2024-03-19 13:20:11.518655: E external/xla/xla/stream_executor/cuda/cuda_driver.cc:674] failed to unload module 0xaaaf560; leaking: CUDA_ERROR_ILLEGAL_ADDRESS: an illegal memory access was encountered
2024-03-19 13:20:11.519606: E external/xla/xla/stream_executor/cuda/cuda_driver.cc:674] failed to unload module 0xae18500; leaking: CUDA_ERROR_ILLEGAL_ADDRESS: an illegal memory access was encountered
2024-03-19 13:20:11.520163: E external/xla/xla/stream_executor/cuda/cuda_driver.cc:674] failed to unload module 0x3c38da0; leaking: CUDA_ERROR_ILLEGAL_ADDRESS: an illegal memory access was encountered
2024-03-19 13:20:11.524416: E external/xla/xla/stream_executor/cuda/cuda_driver.cc:674] failed to unload module 0x382a9c0; leaking: CUDA_ERROR_ILLEGAL_ADDRESS: an illegal memory access was encountered
2024-03-19 13:20:11.524769: E external/xla/xla/stream_executor/cuda/cuda_driver.cc:674] failed to unload module 0x92e1230; leaking: CUDA_ERROR_ILLEGAL_ADDRESS: an illegal memory access was encountered
2024-03-19 13:20:11.525397: E external/xla/xla/stream_executor/cuda/cuda_driver.cc:674] failed to unload module 0x37774d0; leaking: CUDA_ERROR_ILLEGAL_ADDRESS: an illegal memory access was encountered
2024-03-19 13:20:11.525816: E external/xla/xla/stream_executor/cuda/cuda_driver.cc:674] failed to unload module 0x3b95380; leaking: CUDA_ERROR_ILLEGAL_ADDRESS: an illegal memory access was encountered
2024-03-19 13:20:11.526110: E external/xla/xla/stream_executor/cuda/cuda_driver.cc:674] failed to unload module 0x3cd2d90; leaking: CUDA_ERROR_ILLEGAL_ADDRESS: an illegal memory access was encountered
2024-03-19 13:20:11.526433: E external/xla/xla/stream_executor/cuda/cuda_driver.cc:674] failed to unload module 0x3cf90c0; leaking: CUDA_ERROR_ILLEGAL_ADDRESS: an illegal memory access was encountered
2024-03-19 13:20:11.526685: E external/xla/xla/stream_executor/cuda/cuda_driver.cc:674] failed to unload module 0x3902530; leaking: CUDA_ERROR_ILLEGAL_ADDRESS: an illegal memory access was encountered
2024-03-19 13:20:11.527600: E external/xla/xla/stream_executor/cuda/cuda_driver.cc:674] failed to unload module 0xb490e60; leaking: CUDA_ERROR_ILLEGAL_ADDRESS: an illegal memory access was encountered
2024-03-19 13:20:11.527961: E external/xla/xla/stream_executor/cuda/cuda_driver.cc:674] failed to unload module 0xb793f70; leaking: CUDA_ERROR_ILLEGAL_ADDRESS: an illegal memory access was encountered
2024-03-19 13:20:11.528276: E external/xla/xla/stream_executor/cuda/cuda_driver.cc:674] failed to unload module 0xb7a0d30; leaking: CUDA_ERROR_ILLEGAL_ADDRESS: an illegal memory access was encountered
2024-03-19 13:20:11.528579: E external/xla/xla/stream_executor/cuda/cuda_driver.cc:674] failed to unload module 0xb7640f0; leaking: CUDA_ERROR_ILLEGAL_ADDRESS: an illegal memory access was encountered
2024-03-19 13:20:11.529251: E external/xla/xla/stream_executor/cuda/cuda_driver.cc:674] failed to unload module 0xb9b1520; leaking: CUDA_ERROR_ILLEGAL_ADDRESS: an illegal memory access was encountered
2024-03-19 13:20:11.529887: E external/xla/xla/stream_executor/cuda/cuda_driver.cc:674] failed to unload module 0xadfe5b0; leaking: CUDA_ERROR_ILLEGAL_ADDRESS: an illegal memory access was encountered
2024-03-19 13:20:11.530179: E external/xla/xla/stream_executor/cuda/cuda_driver.cc:674] failed to unload module 0xaf45500; leaking: CUDA_ERROR_ILLEGAL_ADDRESS: an illegal memory access was encountered
2024-03-19 13:20:11.531697: E external/xla/xla/stream_executor/cuda/cuda_driver.cc:674] failed to unload module 0xbcd4350; leaking: CUDA_ERROR_ILLEGAL_ADDRESS: an illegal memory access was encountered
2024-03-19 13:20:11.532854: E external/xla/xla/stream_executor/cuda/cuda_driver.cc:674] failed to unload module 0xae43dd0; leaking: CUDA_ERROR_ILLEGAL_ADDRESS: an illegal memory access was encountered
2024-03-19 13:20:11.534138: E external/xla/xla/stream_executor/cuda/cuda_driver.cc:674] failed to unload module 0x7f562cf7c850; leaking: CUDA_ERROR_ILLEGAL_ADDRESS: an illegal memory access was encountered
2024-03-19 13:20:11.536402: E external/xla/xla/stream_executor/cuda/cuda_driver.cc:674] failed to unload module 0x7f562d5da0b0; leaking: CUDA_ERROR_ILLEGAL_ADDRESS: an illegal memory access was encountered
2024-03-19 13:20:11.537920: E external/xla/xla/stream_executor/cuda/cuda_driver.cc:674] failed to unload module 0x7f562d911b50; leaking: CUDA_ERROR_ILLEGAL_ADDRESS: an illegal memory access was encountered
2024-03-19 13:20:11.539305: E external/xla/xla/stream_executor/cuda/cuda_driver.cc:674] failed to unload module 0x7f562ddd2e90; leaking: CUDA_ERROR_ILLEGAL_ADDRESS: an illegal memory access was encountered
2024-03-19 13:20:11.771397: E external/xla/xla/stream_executor/cuda/cuda_driver.cc:763] failed to free device memory at 0x7f55fb747a00; result: CUDA_ERROR_ILLEGAL_ADDRESS: an illegal memory access was encountered
2024-03-19 13:20:11.772046: E external/xla/xla/stream_executor/cuda/cuda_driver.cc:674] failed to unload module 0x7f562e2ead80; leaking: CUDA_ERROR_ILLEGAL_ADDRESS: an illegal memory access was encountered
