Loaded dependency [python3/3.10.12]: gcc/11.4.0-binutils-2.40
Loaded dependency [python3/3.10.12]: sqlite3/3.42.0

Switching from python3/3.8.2 to python3/3.10.12
  Loading requirement: gcc/11.4.0-binutils-2.40 sqlite3/3.42.0
2024-01-16 01:32:27.136470: E tensorflow/compiler/xla/stream_executor/cuda/cuda_dnn.cc:9342] Unable to register cuDNN factory: Attempting to register factory for plugin cuDNN when one has already been registered
2024-01-16 01:32:27.136518: E tensorflow/compiler/xla/stream_executor/cuda/cuda_fft.cc:609] Unable to register cuFFT factory: Attempting to register factory for plugin cuFFT when one has already been registered
2024-01-16 01:32:27.139619: E tensorflow/compiler/xla/stream_executor/cuda/cuda_blas.cc:1518] Unable to register cuBLAS factory: Attempting to register factory for plugin cuBLAS when one has already been registered
2024-01-16 01:33:35.314407: W external/xla/xla/service/gpu/runtime/support.cc:58] Intercepted XLA runtime error:
INTERNAL: jaxlib/gpu/blas_kernels.cc:100: operation gpuStreamSynchronize(stream) failed: an illegal memory access was encountered
2024-01-16 01:33:35.314763: E external/xla/xla/pjrt/pjrt_stream_executor_client.cc:2593] Execution of replica 0 failed: INTERNAL: Failed to execute XLA Runtime executable: run time error: custom call 'xla.gpu.custom_call' failed: jaxlib/gpu/blas_kernels.cc:100: operation gpuStreamSynchronize(stream) failed: an illegal memory access was encountered; current tracing scope: custom-call.4; current profiling annotation: XlaModule:#hlo_module=jit__lambda_,program_id=131#.
2024-01-16 01:33:35.408867: W tensorflow/core/framework/op_kernel.cc:1827] UNKNOWN: XlaRuntimeError: INTERNAL: Failed to execute XLA Runtime executable: run time error: custom call 'xla.gpu.custom_call' failed: jaxlib/gpu/blas_kernels.cc:100: operation gpuStreamSynchronize(stream) failed: an illegal memory access was encountered; current tracing scope: custom-call.4; current profiling annotation: XlaModule:#hlo_module=jit__lambda_,program_id=131#.
jax.errors.SimplifiedTraceback: For simplicity, JAX has removed its internal frames from the traceback of the following exception. Set JAX_TRACEBACK_FILTERING=off to include these.


The above exception was the direct cause of the following exception:


Traceback (most recent call last):

  File "/zhome/77/8/118225/.local/lib/python3.10/site-packages/tensorflow/python/ops/script_ops.py", line 270, in __call__
    ret = func(*args)

  File "/zhome/77/8/118225/.local/lib/python3.10/site-packages/tensorflow/python/autograph/impl/api.py", line 643, in wrapper
    return func(*args, **kwargs)

  File "/zhome/77/8/118225/.local/lib/python3.10/site-packages/tensorflow/python/data/ops/from_generator_op.py", line 198, in generator_py_func
    values = next(generator_state.get_iterator(iterator_id))

  File "/zhome/77/8/118225/Desktop/Projects/score_diffusion_mean/score_diffusion_mean/jaxgeometry/statistics/score_matching/generators.py", line 66, in __call__
    (ts,xss,chartss,*_) = self.product((jnp.repeat(self.x0s[0],self.x_samples,axis=0),

jaxlib.xla_extension.XlaRuntimeError: INTERNAL: Failed to execute XLA Runtime executable: run time error: custom call 'xla.gpu.custom_call' failed: jaxlib/gpu/blas_kernels.cc:100: operation gpuStreamSynchronize(stream) failed: an illegal memory access was encountered; current tracing scope: custom-call.4; current profiling annotation: XlaModule:#hlo_module=jit__lambda_,program_id=131#.


Traceback (most recent call last):
  File "/zhome/77/8/118225/Desktop/Projects/score_diffusion_mean/score_diffusion_mean/train_score.py", line 483, in <module>
    train_score()
  File "/zhome/77/8/118225/Desktop/Projects/score_diffusion_mean/score_diffusion_mean/train_score.py", line 438, in train_score
    train_s2(M=M,
  File "/zhome/77/8/118225/Desktop/Projects/score_diffusion_mean/score_diffusion_mean/jaxgeometry/statistics/score_matching/trainxt.py", line 251, in train_s2
    initial_params = s2_model.init(jrandom.PRNGKey(seed), next(train_dataset)[:,:(2*N_dim+1)])
  File "/zhome/77/8/118225/.local/lib/python3.10/site-packages/tensorflow_datasets/core/dataset_utils.py", line 82, in _eager_dataset_iterator
    for elem in ds:
  File "/zhome/77/8/118225/.local/lib/python3.10/site-packages/tensorflow/python/data/ops/iterator_ops.py", line 809, in __next__
    return self._next_internal()
  File "/zhome/77/8/118225/.local/lib/python3.10/site-packages/tensorflow/python/data/ops/iterator_ops.py", line 772, in _next_internal
    ret = gen_dataset_ops.iterator_get_next(
  File "/zhome/77/8/118225/.local/lib/python3.10/site-packages/tensorflow/python/ops/gen_dataset_ops.py", line 3028, in iterator_get_next
    _ops.raise_from_not_ok_status(e, name)
  File "/zhome/77/8/118225/.local/lib/python3.10/site-packages/tensorflow/python/framework/ops.py", line 5888, in raise_from_not_ok_status
    raise core._status_to_exception(e) from None  # pylint: disable=protected-access
tensorflow.python.framework.errors_impl.UnknownError: {{function_node __wrapped__IteratorGetNext_output_types_1_device_/job:localhost/replica:0/task:0/device:CPU:0}} XlaRuntimeError: INTERNAL: Failed to execute XLA Runtime executable: run time error: custom call 'xla.gpu.custom_call' failed: jaxlib/gpu/blas_kernels.cc:100: operation gpuStreamSynchronize(stream) failed: an illegal memory access was encountered; current tracing scope: custom-call.4; current profiling annotation: XlaModule:#hlo_module=jit__lambda_,program_id=131#.
jax.errors.SimplifiedTraceback: For simplicity, JAX has removed its internal frames from the traceback of the following exception. Set JAX_TRACEBACK_FILTERING=off to include these.


The above exception was the direct cause of the following exception:


Traceback (most recent call last):

  File "/zhome/77/8/118225/.local/lib/python3.10/site-packages/tensorflow/python/ops/script_ops.py", line 270, in __call__
    ret = func(*args)

  File "/zhome/77/8/118225/.local/lib/python3.10/site-packages/tensorflow/python/autograph/impl/api.py", line 643, in wrapper
    return func(*args, **kwargs)

  File "/zhome/77/8/118225/.local/lib/python3.10/site-packages/tensorflow/python/data/ops/from_generator_op.py", line 198, in generator_py_func
    values = next(generator_state.get_iterator(iterator_id))

  File "/zhome/77/8/118225/Desktop/Projects/score_diffusion_mean/score_diffusion_mean/jaxgeometry/statistics/score_matching/generators.py", line 66, in __call__
    (ts,xss,chartss,*_) = self.product((jnp.repeat(self.x0s[0],self.x_samples,axis=0),

jaxlib.xla_extension.XlaRuntimeError: INTERNAL: Failed to execute XLA Runtime executable: run time error: custom call 'xla.gpu.custom_call' failed: jaxlib/gpu/blas_kernels.cc:100: operation gpuStreamSynchronize(stream) failed: an illegal memory access was encountered; current tracing scope: custom-call.4; current profiling annotation: XlaModule:#hlo_module=jit__lambda_,program_id=131#.


	 [[{{node PyFunc}}]] [Op:IteratorGetNext] name: 
2024-01-16 01:33:36.103208: E external/xla/xla/stream_executor/cuda/cuda_driver.cc:674] failed to unload module 0x873c390; leaking: CUDA_ERROR_ILLEGAL_ADDRESS: an illegal memory access was encountered
2024-01-16 01:33:36.104636: E external/xla/xla/stream_executor/cuda/cuda_driver.cc:674] failed to unload module 0x7fe36c1e53d0; leaking: CUDA_ERROR_ILLEGAL_ADDRESS: an illegal memory access was encountered
2024-01-16 01:33:36.107263: E external/xla/xla/stream_executor/cuda/cuda_driver.cc:674] failed to unload module 0x9153ef0; leaking: CUDA_ERROR_ILLEGAL_ADDRESS: an illegal memory access was encountered
2024-01-16 01:33:36.109478: E external/xla/xla/stream_executor/cuda/cuda_driver.cc:674] failed to unload module 0xad6cec0; leaking: CUDA_ERROR_ILLEGAL_ADDRESS: an illegal memory access was encountered
2024-01-16 01:33:36.113731: E external/xla/xla/stream_executor/cuda/cuda_driver.cc:674] failed to unload module 0x89180e0; leaking: CUDA_ERROR_ILLEGAL_ADDRESS: an illegal memory access was encountered
2024-01-16 01:33:36.114626: E external/xla/xla/stream_executor/cuda/cuda_driver.cc:674] failed to unload module 0x87f6490; leaking: CUDA_ERROR_ILLEGAL_ADDRESS: an illegal memory access was encountered
2024-01-16 01:33:36.115091: E external/xla/xla/stream_executor/cuda/cuda_driver.cc:674] failed to unload module 0x87a9280; leaking: CUDA_ERROR_ILLEGAL_ADDRESS: an illegal memory access was encountered
2024-01-16 01:33:36.115556: E external/xla/xla/stream_executor/cuda/cuda_driver.cc:674] failed to unload module 0x87170f0; leaking: CUDA_ERROR_ILLEGAL_ADDRESS: an illegal memory access was encountered
2024-01-16 01:33:36.115989: E external/xla/xla/stream_executor/cuda/cuda_driver.cc:674] failed to unload module 0x8d97690; leaking: CUDA_ERROR_ILLEGAL_ADDRESS: an illegal memory access was encountered
2024-01-16 01:33:36.116395: E external/xla/xla/stream_executor/cuda/cuda_driver.cc:674] failed to unload module 0x7c0e6a0; leaking: CUDA_ERROR_ILLEGAL_ADDRESS: an illegal memory access was encountered
2024-01-16 01:33:36.118592: E external/xla/xla/stream_executor/cuda/cuda_driver.cc:674] failed to unload module 0xb212bc0; leaking: CUDA_ERROR_ILLEGAL_ADDRESS: an illegal memory access was encountered
2024-01-16 01:33:36.119572: E external/xla/xla/stream_executor/cuda/cuda_driver.cc:674] failed to unload module 0xa219a50; leaking: CUDA_ERROR_ILLEGAL_ADDRESS: an illegal memory access was encountered
2024-01-16 01:33:36.120045: E external/xla/xla/stream_executor/cuda/cuda_driver.cc:674] failed to unload module 0xad85660; leaking: CUDA_ERROR_ILLEGAL_ADDRESS: an illegal memory access was encountered
2024-01-16 01:33:36.122323: E external/xla/xla/stream_executor/cuda/cuda_driver.cc:674] failed to unload module 0xb0f0860; leaking: CUDA_ERROR_ILLEGAL_ADDRESS: an illegal memory access was encountered
2024-01-16 01:33:36.123977: E external/xla/xla/stream_executor/cuda/cuda_driver.cc:674] failed to unload module 0xb43c650; leaking: CUDA_ERROR_ILLEGAL_ADDRESS: an illegal memory access was encountered
2024-01-16 01:33:36.125775: E external/xla/xla/stream_executor/cuda/cuda_driver.cc:674] failed to unload module 0x7fe36c178550; leaking: CUDA_ERROR_ILLEGAL_ADDRESS: an illegal memory access was encountered
2024-01-16 01:33:36.129674: E external/xla/xla/stream_executor/cuda/cuda_driver.cc:674] failed to unload module 0x7fe36cb7fbe0; leaking: CUDA_ERROR_ILLEGAL_ADDRESS: an illegal memory access was encountered
2024-01-16 01:33:36.131901: E external/xla/xla/stream_executor/cuda/cuda_driver.cc:674] failed to unload module 0x7fe36c80d2a0; leaking: CUDA_ERROR_ILLEGAL_ADDRESS: an illegal memory access was encountered
2024-01-16 01:33:36.134058: E external/xla/xla/stream_executor/cuda/cuda_driver.cc:674] failed to unload module 0x7fe36c9fe8c0; leaking: CUDA_ERROR_ILLEGAL_ADDRESS: an illegal memory access was encountered
2024-01-16 01:33:36.383040: E external/xla/xla/stream_executor/cuda/cuda_driver.cc:763] failed to free device memory at 0x7fe34bf46400; result: CUDA_ERROR_ILLEGAL_ADDRESS: an illegal memory access was encountered
2024-01-16 01:33:36.384090: E external/xla/xla/stream_executor/cuda/cuda_driver.cc:674] failed to unload module 0x7fe36d7d5ec0; leaking: CUDA_ERROR_ILLEGAL_ADDRESS: an illegal memory access was encountered
