Loaded dependency [python3/3.10.12]: gcc/11.4.0-binutils-2.40
Loaded dependency [python3/3.10.12]: sqlite3/3.42.0

Switching from python3/3.8.2 to python3/3.10.12
  Loading requirement: gcc/11.4.0-binutils-2.40 sqlite3/3.42.0
2024-03-01 06:59:10.237993: E tensorflow/compiler/xla/stream_executor/cuda/cuda_dnn.cc:9342] Unable to register cuDNN factory: Attempting to register factory for plugin cuDNN when one has already been registered
2024-03-01 06:59:10.238070: E tensorflow/compiler/xla/stream_executor/cuda/cuda_fft.cc:609] Unable to register cuFFT factory: Attempting to register factory for plugin cuFFT when one has already been registered
2024-03-01 06:59:10.253548: E tensorflow/compiler/xla/stream_executor/cuda/cuda_blas.cc:1518] Unable to register cuBLAS factory: Attempting to register factory for plugin cuBLAS when one has already been registered
2024-03-01 06:59:45.710431: W external/xla/xla/service/gpu/runtime/support.cc:58] Intercepted XLA runtime error:
INTERNAL: jaxlib/gpu/blas_kernels.cc:100: operation gpuStreamSynchronize(stream) failed: an illegal memory access was encountered
2024-03-01 06:59:45.710895: E external/xla/xla/pjrt/pjrt_stream_executor_client.cc:2593] Execution of replica 0 failed: INTERNAL: Failed to execute XLA Runtime executable: run time error: custom call 'xla.gpu.custom_call' failed: jaxlib/gpu/blas_kernels.cc:100: operation gpuStreamSynchronize(stream) failed: an illegal memory access was encountered; current tracing scope: custom-call.4; current profiling annotation: XlaModule:#hlo_module=jit__lambda_,program_id=143#.
2024-03-01 06:59:45.804365: W tensorflow/core/framework/op_kernel.cc:1827] UNKNOWN: XlaRuntimeError: INTERNAL: Failed to execute XLA Runtime executable: run time error: custom call 'xla.gpu.custom_call' failed: jaxlib/gpu/blas_kernels.cc:100: operation gpuStreamSynchronize(stream) failed: an illegal memory access was encountered; current tracing scope: custom-call.4; current profiling annotation: XlaModule:#hlo_module=jit__lambda_,program_id=143#.
jax.errors.SimplifiedTraceback: For simplicity, JAX has removed its internal frames from the traceback of the following exception. Set JAX_TRACEBACK_FILTERING=off to include these.


The above exception was the direct cause of the following exception:


Traceback (most recent call last):

  File "/zhome/77/8/118225/.local/lib/python3.10/site-packages/tensorflow/python/ops/script_ops.py", line 270, in __call__
    ret = func(*args)

  File "/zhome/77/8/118225/.local/lib/python3.10/site-packages/tensorflow/python/autograph/impl/api.py", line 643, in wrapper
    return func(*args, **kwargs)

  File "/zhome/77/8/118225/.local/lib/python3.10/site-packages/tensorflow/python/data/ops/from_generator_op.py", line 198, in generator_py_func
    values = next(generator_state.get_iterator(iterator_id))

  File "/zhome/77/8/118225/Desktop/Projects/score_diffusion_mean/score_diffusion_mean/jaxgeometry/statistics/score_matching/generators.py", line 78, in __call__
    (ts,xss,chartss,*_) = self.product((jnp.repeat(self.x0s[0],self.x_samples,axis=0),

jaxlib.xla_extension.XlaRuntimeError: INTERNAL: Failed to execute XLA Runtime executable: run time error: custom call 'xla.gpu.custom_call' failed: jaxlib/gpu/blas_kernels.cc:100: operation gpuStreamSynchronize(stream) failed: an illegal memory access was encountered; current tracing scope: custom-call.4; current profiling annotation: XlaModule:#hlo_module=jit__lambda_,program_id=143#.


Traceback (most recent call last):
  File "/zhome/77/8/118225/Desktop/Projects/score_diffusion_mean/score_diffusion_mean/train_score.py", line 346, in <module>
    train_score()
  File "/zhome/77/8/118225/Desktop/Projects/score_diffusion_mean/score_diffusion_mean/train_score.py", line 324, in train_score
    train_s1(M=M,
  File "/zhome/77/8/118225/Desktop/Projects/score_diffusion_mean/score_diffusion_mean/jaxgeometry/statistics/score_matching/trainxt.py", line 94, in train_s1
    initial_params = model.init(jrandom.PRNGKey(seed), next(train_dataset)[:,:(2*N_dim+1)])
  File "/zhome/77/8/118225/.local/lib/python3.10/site-packages/tensorflow_datasets/core/dataset_utils.py", line 82, in _eager_dataset_iterator
    for elem in ds:
  File "/zhome/77/8/118225/.local/lib/python3.10/site-packages/tensorflow/python/data/ops/iterator_ops.py", line 809, in __next__
    return self._next_internal()
  File "/zhome/77/8/118225/.local/lib/python3.10/site-packages/tensorflow/python/data/ops/iterator_ops.py", line 772, in _next_internal
    ret = gen_dataset_ops.iterator_get_next(
  File "/zhome/77/8/118225/.local/lib/python3.10/site-packages/tensorflow/python/ops/gen_dataset_ops.py", line 3028, in iterator_get_next
    _ops.raise_from_not_ok_status(e, name)
  File "/zhome/77/8/118225/.local/lib/python3.10/site-packages/tensorflow/python/framework/ops.py", line 5888, in raise_from_not_ok_status
    raise core._status_to_exception(e) from None  # pylint: disable=protected-access
tensorflow.python.framework.errors_impl.UnknownError: {{function_node __wrapped__IteratorGetNext_output_types_1_device_/job:localhost/replica:0/task:0/device:CPU:0}} XlaRuntimeError: INTERNAL: Failed to execute XLA Runtime executable: run time error: custom call 'xla.gpu.custom_call' failed: jaxlib/gpu/blas_kernels.cc:100: operation gpuStreamSynchronize(stream) failed: an illegal memory access was encountered; current tracing scope: custom-call.4; current profiling annotation: XlaModule:#hlo_module=jit__lambda_,program_id=143#.
jax.errors.SimplifiedTraceback: For simplicity, JAX has removed its internal frames from the traceback of the following exception. Set JAX_TRACEBACK_FILTERING=off to include these.


The above exception was the direct cause of the following exception:


Traceback (most recent call last):

  File "/zhome/77/8/118225/.local/lib/python3.10/site-packages/tensorflow/python/ops/script_ops.py", line 270, in __call__
    ret = func(*args)

  File "/zhome/77/8/118225/.local/lib/python3.10/site-packages/tensorflow/python/autograph/impl/api.py", line 643, in wrapper
    return func(*args, **kwargs)

  File "/zhome/77/8/118225/.local/lib/python3.10/site-packages/tensorflow/python/data/ops/from_generator_op.py", line 198, in generator_py_func
    values = next(generator_state.get_iterator(iterator_id))

  File "/zhome/77/8/118225/Desktop/Projects/score_diffusion_mean/score_diffusion_mean/jaxgeometry/statistics/score_matching/generators.py", line 78, in __call__
    (ts,xss,chartss,*_) = self.product((jnp.repeat(self.x0s[0],self.x_samples,axis=0),

jaxlib.xla_extension.XlaRuntimeError: INTERNAL: Failed to execute XLA Runtime executable: run time error: custom call 'xla.gpu.custom_call' failed: jaxlib/gpu/blas_kernels.cc:100: operation gpuStreamSynchronize(stream) failed: an illegal memory access was encountered; current tracing scope: custom-call.4; current profiling annotation: XlaModule:#hlo_module=jit__lambda_,program_id=143#.


	 [[{{node PyFunc}}]] [Op:IteratorGetNext] name: 
2024-03-01 06:59:46.389779: E external/xla/xla/stream_executor/cuda/cuda_driver.cc:674] failed to unload module 0x9118420; leaking: CUDA_ERROR_ILLEGAL_ADDRESS: an illegal memory access was encountered
2024-03-01 06:59:46.391045: E external/xla/xla/stream_executor/cuda/cuda_driver.cc:674] failed to unload module 0xdbc4180; leaking: CUDA_ERROR_ILLEGAL_ADDRESS: an illegal memory access was encountered
2024-03-01 06:59:46.393233: E external/xla/xla/stream_executor/cuda/cuda_driver.cc:674] failed to unload module 0xa6b7870; leaking: CUDA_ERROR_ILLEGAL_ADDRESS: an illegal memory access was encountered
2024-03-01 06:59:46.395850: E external/xla/xla/stream_executor/cuda/cuda_driver.cc:674] failed to unload module 0xb7f21a0; leaking: CUDA_ERROR_ILLEGAL_ADDRESS: an illegal memory access was encountered
2024-03-01 06:59:46.396777: E external/xla/xla/stream_executor/cuda/cuda_driver.cc:674] failed to unload module 0xc7e3460; leaking: CUDA_ERROR_ILLEGAL_ADDRESS: an illegal memory access was encountered
2024-03-01 06:59:46.401656: E external/xla/xla/stream_executor/cuda/cuda_driver.cc:674] failed to unload module 0x9da5dc0; leaking: CUDA_ERROR_ILLEGAL_ADDRESS: an illegal memory access was encountered
2024-03-01 06:59:46.402439: E external/xla/xla/stream_executor/cuda/cuda_driver.cc:674] failed to unload module 0x9dacbc0; leaking: CUDA_ERROR_ILLEGAL_ADDRESS: an illegal memory access was encountered
2024-03-01 06:59:46.402796: E external/xla/xla/stream_executor/cuda/cuda_driver.cc:674] failed to unload module 0xa1d1e80; leaking: CUDA_ERROR_ILLEGAL_ADDRESS: an illegal memory access was encountered
2024-03-01 06:59:46.403160: E external/xla/xla/stream_executor/cuda/cuda_driver.cc:674] failed to unload module 0x91aa8f0; leaking: CUDA_ERROR_ILLEGAL_ADDRESS: an illegal memory access was encountered
2024-03-01 06:59:46.403504: E external/xla/xla/stream_executor/cuda/cuda_driver.cc:674] failed to unload module 0xa16c3a0; leaking: CUDA_ERROR_ILLEGAL_ADDRESS: an illegal memory access was encountered
2024-03-01 06:59:46.403855: E external/xla/xla/stream_executor/cuda/cuda_driver.cc:674] failed to unload module 0xa4354b0; leaking: CUDA_ERROR_ILLEGAL_ADDRESS: an illegal memory access was encountered
2024-03-01 06:59:46.404765: E external/xla/xla/stream_executor/cuda/cuda_driver.cc:674] failed to unload module 0xcb1f310; leaking: CUDA_ERROR_ILLEGAL_ADDRESS: an illegal memory access was encountered
2024-03-01 06:59:46.405147: E external/xla/xla/stream_executor/cuda/cuda_driver.cc:674] failed to unload module 0xcc14440; leaking: CUDA_ERROR_ILLEGAL_ADDRESS: an illegal memory access was encountered
2024-03-01 06:59:46.405495: E external/xla/xla/stream_executor/cuda/cuda_driver.cc:674] failed to unload module 0xcdd5210; leaking: CUDA_ERROR_ILLEGAL_ADDRESS: an illegal memory access was encountered
2024-03-01 06:59:46.406269: E external/xla/xla/stream_executor/cuda/cuda_driver.cc:674] failed to unload module 0xd011590; leaking: CUDA_ERROR_ILLEGAL_ADDRESS: an illegal memory access was encountered
2024-03-01 06:59:46.407021: E external/xla/xla/stream_executor/cuda/cuda_driver.cc:674] failed to unload module 0xc465700; leaking: CUDA_ERROR_ILLEGAL_ADDRESS: an illegal memory access was encountered
2024-03-01 06:59:46.407371: E external/xla/xla/stream_executor/cuda/cuda_driver.cc:674] failed to unload module 0xc574370; leaking: CUDA_ERROR_ILLEGAL_ADDRESS: an illegal memory access was encountered
2024-03-01 06:59:46.409249: E external/xla/xla/stream_executor/cuda/cuda_driver.cc:674] failed to unload module 0xd0eb730; leaking: CUDA_ERROR_ILLEGAL_ADDRESS: an illegal memory access was encountered
2024-03-01 06:59:46.410646: E external/xla/xla/stream_executor/cuda/cuda_driver.cc:674] failed to unload module 0xca0f190; leaking: CUDA_ERROR_ILLEGAL_ADDRESS: an illegal memory access was encountered
2024-03-01 06:59:46.412166: E external/xla/xla/stream_executor/cuda/cuda_driver.cc:674] failed to unload module 0xdcffee0; leaking: CUDA_ERROR_ILLEGAL_ADDRESS: an illegal memory access was encountered
2024-03-01 06:59:46.415143: E external/xla/xla/stream_executor/cuda/cuda_driver.cc:674] failed to unload module 0xde65200; leaking: CUDA_ERROR_ILLEGAL_ADDRESS: an illegal memory access was encountered
2024-03-01 06:59:46.417166: E external/xla/xla/stream_executor/cuda/cuda_driver.cc:674] failed to unload module 0xe45c2a0; leaking: CUDA_ERROR_ILLEGAL_ADDRESS: an illegal memory access was encountered
2024-03-01 06:59:46.419027: E external/xla/xla/stream_executor/cuda/cuda_driver.cc:674] failed to unload module 0xed5f0a0; leaking: CUDA_ERROR_ILLEGAL_ADDRESS: an illegal memory access was encountered
2024-03-01 06:59:46.684874: E external/xla/xla/stream_executor/cuda/cuda_driver.cc:763] failed to free device memory at 0x7f729f747a00; result: CUDA_ERROR_ILLEGAL_ADDRESS: an illegal memory access was encountered
2024-03-01 06:59:46.685640: E external/xla/xla/stream_executor/cuda/cuda_driver.cc:674] failed to unload module 0xf0ca780; leaking: CUDA_ERROR_ILLEGAL_ADDRESS: an illegal memory access was encountered
