Loaded dependency [python3/3.10.12]: gcc/11.4.0-binutils-2.40
Loaded dependency [python3/3.10.12]: sqlite3/3.42.0

Switching from python3/3.8.2 to python3/3.10.12
  Loading requirement: gcc/11.4.0-binutils-2.40 sqlite3/3.42.0
2024-03-20 07:06:45.866932: E tensorflow/compiler/xla/stream_executor/cuda/cuda_dnn.cc:9342] Unable to register cuDNN factory: Attempting to register factory for plugin cuDNN when one has already been registered
2024-03-20 07:06:45.867007: E tensorflow/compiler/xla/stream_executor/cuda/cuda_fft.cc:609] Unable to register cuFFT factory: Attempting to register factory for plugin cuFFT when one has already been registered
2024-03-20 07:06:45.880426: E tensorflow/compiler/xla/stream_executor/cuda/cuda_blas.cc:1518] Unable to register cuBLAS factory: Attempting to register factory for plugin cuBLAS when one has already been registered
jax.errors.SimplifiedTraceback: For simplicity, JAX has removed its internal frames from the traceback of the following exception. Set JAX_TRACEBACK_FILTERING=off to include these.

The above exception was the direct cause of the following exception:

Traceback (most recent call last):
  File "/zhome/77/8/118225/Desktop/Projects/score_diffusion_mean/score_diffusion_mean/train_score.py", line 300, in <module>
    train_score()
  File "/zhome/77/8/118225/Desktop/Projects/score_diffusion_mean/score_diffusion_mean/train_score.py", line 224, in train_score
    train_s2(M=M,
  File "/zhome/77/8/118225/Desktop/Projects/score_diffusion_mean/score_diffusion_mean/jaxgeometry/statistics/score_matching/trainxt.py", line 234, in train_s2
    new_state, loss_val = update(state, data)
  File "/zhome/77/8/118225/Desktop/Projects/score_diffusion_mean/score_diffusion_mean/jaxgeometry/statistics/score_matching/trainxt.py", line 183, in update
    loss, gradients = value_and_grad(loss_fun)(state.params, state.state_val, rng_key, data)
  File "/zhome/77/8/118225/Desktop/Projects/score_diffusion_mean/score_diffusion_mean/jaxgeometry/statistics/score_matching/trainxt.py", line 176, in loss_fun
    return loss_model(generator, s1_model, s2_model, params, state_val, rng_key,
  File "/zhome/77/8/118225/Desktop/Projects/score_diffusion_mean/score_diffusion_mean/jaxgeometry/statistics/score_matching/loss_fun.py", line 176, in dsmdiag_s2fun
    return jnp.mean(vmap(f,(0,0,0,0,0))(x0,xt,t,dW,dt))
  File "/zhome/77/8/118225/Desktop/Projects/score_diffusion_mean/score_diffusion_mean/jaxgeometry/statistics/score_matching/loss_fun.py", line 170, in f
    loss_s2 = jnp.eye(s2)+s1*s1+(1-dW*dW/dt)/dt
  File "/zhome/77/8/118225/.local/lib/python3.10/site-packages/jax/_src/numpy/lax_numpy.py", line 2306, in eye
    N_int = core.canonicalize_dim(N, "'N' argument of jnp.eye()")
TypeError: Shapes must be 1D sequences of concrete values of integer type, got (Traced<ShapedArray(float64[3,3])>with<BatchTrace(level=5/0)> with
  val = Traced<ShapedArray(float64[262144,3,3])>with<DynamicJaxprTrace(level=4/0)>
  batch_dim = 0,). 'N' argument of jnp.eye().
If using `jit`, try using `static_argnums` or applying `jit` to smaller subfunctions.
This BatchTracer with object id 139753825806720 was created on line:
  /zhome/77/8/118225/Desktop/Projects/score_diffusion_mean/score_diffusion_mean/models/models.py:136 (__call__)
2024-03-20 07:07:19.564423: W tensorflow/core/kernels/data/generator_dataset_op.cc:108] Error occurred when finalizing GeneratorDataset iterator: FAILED_PRECONDITION: Python interpreter state is not initialized. The process may be terminated.
	 [[{{node PyFunc}}]]
