Loaded dependency [python3/3.10.12]: gcc/11.4.0-binutils-2.40
Loaded dependency [python3/3.10.12]: sqlite3/3.42.0

Switching from python3/3.8.2 to python3/3.10.12
  Loading requirement: gcc/11.4.0-binutils-2.40 sqlite3/3.42.0
2024-02-03 15:45:36.357427: E tensorflow/compiler/xla/stream_executor/cuda/cuda_dnn.cc:9342] Unable to register cuDNN factory: Attempting to register factory for plugin cuDNN when one has already been registered
2024-02-03 15:45:36.357708: E tensorflow/compiler/xla/stream_executor/cuda/cuda_fft.cc:609] Unable to register cuFFT factory: Attempting to register factory for plugin cuFFT when one has already been registered
2024-02-03 15:45:36.418646: E tensorflow/compiler/xla/stream_executor/cuda/cuda_blas.cc:1518] Unable to register cuBLAS factory: Attempting to register factory for plugin cuBLAS when one has already been registered
2024-02-03 15:46:46.817006: W external/tsl/tsl/framework/bfc_allocator.cc:296] Allocator (GPU_0_bfc) ran out of memory trying to allocate 3.83GiB with freed_by_count=0. The caller indicates that this is not a failure, but this may mean that there could be performance gains if more memory were available.
2024-02-03 15:46:47.196958: W tensorflow/core/framework/op_kernel.cc:1827] UNKNOWN: XlaRuntimeError: RESOURCE_EXHAUSTED: Out of memory while trying to allocate 4112777216 bytes.
jax.errors.SimplifiedTraceback: For simplicity, JAX has removed its internal frames from the traceback of the following exception. Set JAX_TRACEBACK_FILTERING=off to include these.


The above exception was the direct cause of the following exception:


Traceback (most recent call last):

  File "/zhome/77/8/118225/.local/lib/python3.10/site-packages/tensorflow/python/ops/script_ops.py", line 270, in __call__
    ret = func(*args)

  File "/zhome/77/8/118225/.local/lib/python3.10/site-packages/tensorflow/python/autograph/impl/api.py", line 643, in wrapper
    return func(*args, **kwargs)

  File "/zhome/77/8/118225/.local/lib/python3.10/site-packages/tensorflow/python/data/ops/from_generator_op.py", line 198, in generator_py_func
    values = next(generator_state.get_iterator(iterator_id))

  File "/zhome/77/8/118225/Desktop/Projects/score_diffusion_mean/score_diffusion_mean/jaxgeometry/statistics/score_matching/generators.py", line 66, in __call__
    (ts,xss,chartss,*_) = self.product((jnp.repeat(self.x0s[0],self.x_samples,axis=0),

jaxlib.xla_extension.XlaRuntimeError: RESOURCE_EXHAUSTED: Out of memory while trying to allocate 4112777216 bytes.


Traceback (most recent call last):
  File "/zhome/77/8/118225/Desktop/Projects/score_diffusion_mean/score_diffusion_mean/train_score.py", line 545, in <module>
    train_score()
  File "/zhome/77/8/118225/Desktop/Projects/score_diffusion_mean/score_diffusion_mean/train_score.py", line 523, in train_score
    train_s1(M=M,
  File "/zhome/77/8/118225/Desktop/Projects/score_diffusion_mean/score_diffusion_mean/jaxgeometry/statistics/score_matching/trainxt.py", line 131, in train_s1
    initial_params = model.init(jrandom.PRNGKey(seed), next(train_dataset)[:,:(2*N_dim+1)])
  File "/zhome/77/8/118225/.local/lib/python3.10/site-packages/tensorflow_datasets/core/dataset_utils.py", line 82, in _eager_dataset_iterator
    for elem in ds:
  File "/zhome/77/8/118225/.local/lib/python3.10/site-packages/tensorflow/python/data/ops/iterator_ops.py", line 809, in __next__
    return self._next_internal()
  File "/zhome/77/8/118225/.local/lib/python3.10/site-packages/tensorflow/python/data/ops/iterator_ops.py", line 772, in _next_internal
    ret = gen_dataset_ops.iterator_get_next(
  File "/zhome/77/8/118225/.local/lib/python3.10/site-packages/tensorflow/python/ops/gen_dataset_ops.py", line 3028, in iterator_get_next
    _ops.raise_from_not_ok_status(e, name)
  File "/zhome/77/8/118225/.local/lib/python3.10/site-packages/tensorflow/python/framework/ops.py", line 5888, in raise_from_not_ok_status
    raise core._status_to_exception(e) from None  # pylint: disable=protected-access
tensorflow.python.framework.errors_impl.UnknownError: {{function_node __wrapped__IteratorGetNext_output_types_1_device_/job:localhost/replica:0/task:0/device:CPU:0}} XlaRuntimeError: RESOURCE_EXHAUSTED: Out of memory while trying to allocate 4112777216 bytes.
jax.errors.SimplifiedTraceback: For simplicity, JAX has removed its internal frames from the traceback of the following exception. Set JAX_TRACEBACK_FILTERING=off to include these.


The above exception was the direct cause of the following exception:


Traceback (most recent call last):

  File "/zhome/77/8/118225/.local/lib/python3.10/site-packages/tensorflow/python/ops/script_ops.py", line 270, in __call__
    ret = func(*args)

  File "/zhome/77/8/118225/.local/lib/python3.10/site-packages/tensorflow/python/autograph/impl/api.py", line 643, in wrapper
    return func(*args, **kwargs)

  File "/zhome/77/8/118225/.local/lib/python3.10/site-packages/tensorflow/python/data/ops/from_generator_op.py", line 198, in generator_py_func
    values = next(generator_state.get_iterator(iterator_id))

  File "/zhome/77/8/118225/Desktop/Projects/score_diffusion_mean/score_diffusion_mean/jaxgeometry/statistics/score_matching/generators.py", line 66, in __call__
    (ts,xss,chartss,*_) = self.product((jnp.repeat(self.x0s[0],self.x_samples,axis=0),

jaxlib.xla_extension.XlaRuntimeError: RESOURCE_EXHAUSTED: Out of memory while trying to allocate 4112777216 bytes.


	 [[{{node PyFunc}}]] [Op:IteratorGetNext] name: 
