Loaded dependency [python3/3.10.12]: gcc/11.4.0-binutils-2.40
Loaded dependency [python3/3.10.12]: sqlite3/3.42.0

Switching from python3/3.8.2 to python3/3.10.12
  Loading requirement: gcc/11.4.0-binutils-2.40 sqlite3/3.42.0
2024-03-05 17:42:11.187085: E tensorflow/compiler/xla/stream_executor/cuda/cuda_dnn.cc:9342] Unable to register cuDNN factory: Attempting to register factory for plugin cuDNN when one has already been registered
2024-03-05 17:42:11.187128: E tensorflow/compiler/xla/stream_executor/cuda/cuda_fft.cc:609] Unable to register cuFFT factory: Attempting to register factory for plugin cuFFT when one has already been registered
2024-03-05 17:42:11.206022: E tensorflow/compiler/xla/stream_executor/cuda/cuda_blas.cc:1518] Unable to register cuBLAS factory: Attempting to register factory for plugin cuBLAS when one has already been registered
/zhome/77/8/118225/.local/lib/python3.10/site-packages/numpy/core/getlimits.py:518: UserWarning: The value of the smallest subnormal for <class 'numpy.float32'> type is zero.
  setattr(self, word, getattr(machar, word).flat[0])
/zhome/77/8/118225/.local/lib/python3.10/site-packages/numpy/core/getlimits.py:89: UserWarning: The value of the smallest subnormal for <class 'numpy.float32'> type is zero.
  return self._float_to_str(self.smallest_subnormal)
jax.errors.SimplifiedTraceback: For simplicity, JAX has removed its internal frames from the traceback of the following exception. Set JAX_TRACEBACK_FILTERING=off to include these.

The above exception was the direct cause of the following exception:

Traceback (most recent call last):
  File "/zhome/77/8/118225/Desktop/Projects/score_diffusion_mean/score_diffusion_mean/train_score.py", line 360, in <module>
    train_score()
  File "/zhome/77/8/118225/Desktop/Projects/score_diffusion_mean/score_diffusion_mean/train_score.py", line 313, in train_score
    train_s1s2(M=M,
  File "/zhome/77/8/118225/Desktop/Projects/score_diffusion_mean/score_diffusion_mean/jaxgeometry/statistics/score_matching/trainxt.py", line 341, in train_s1s2
    state, loss_val = update(state, data)
  File "/zhome/77/8/118225/Desktop/Projects/score_diffusion_mean/score_diffusion_mean/jaxgeometry/statistics/score_matching/trainxt.py", line 283, in update
    loss, gradients = value_and_grad(loss_fun)(state.params, state.state_val, rng_key, data)
  File "/zhome/77/8/118225/Desktop/Projects/score_diffusion_mean/score_diffusion_mean/jaxgeometry/statistics/score_matching/trainxt.py", line 274, in loss_fun
    s2_loss = loss_s2model(generator, s1_model, s2_model, params, state_val, rng_key,
  File "/zhome/77/8/118225/Desktop/Projects/score_diffusion_mean/score_diffusion_mean/jaxgeometry/statistics/score_matching/loss_fun.py", line 263, in dsmdiagvr_s2fun
    return jnp.mean(vmap(f,(0,0,0,0,0))(x0,xt,t,dW,dt))
  File "/zhome/77/8/118225/Desktop/Projects/score_diffusion_mean/score_diffusion_mean/jaxgeometry/statistics/score_matching/loss_fun.py", line 248, in f
    psi = jnp.diag(s2)+s1*s1
  File "/zhome/77/8/118225/.local/lib/python3.10/site-packages/jax/_src/numpy/lax_numpy.py", line 2862, in diag
    return _diag(v, operator.index(k))
  File "/zhome/77/8/118225/.local/lib/python3.10/site-packages/jax/_src/numpy/lax_numpy.py", line 2876, in _diag
    raise ValueError("diag input must be 1d or 2d")
ValueError: diag input must be 1d or 2d
2024-03-05 17:49:20.858788: W tensorflow/core/kernels/data/generator_dataset_op.cc:108] Error occurred when finalizing GeneratorDataset iterator: FAILED_PRECONDITION: Python interpreter state is not initialized. The process may be terminated.
	 [[{{node PyFunc}}]]
