Loaded dependency [python3/3.10.12]: gcc/11.4.0-binutils-2.40
Loaded dependency [python3/3.10.12]: sqlite3/3.42.0

Switching from python3/3.8.2 to python3/3.10.12
  Loading requirement: gcc/11.4.0-binutils-2.40 sqlite3/3.42.0
2024-02-28 02:32:10.295174: E tensorflow/compiler/xla/stream_executor/cuda/cuda_dnn.cc:9342] Unable to register cuDNN factory: Attempting to register factory for plugin cuDNN when one has already been registered
2024-02-28 02:32:10.295277: E tensorflow/compiler/xla/stream_executor/cuda/cuda_fft.cc:609] Unable to register cuFFT factory: Attempting to register factory for plugin cuFFT when one has already been registered
2024-02-28 02:32:10.302707: E tensorflow/compiler/xla/stream_executor/cuda/cuda_blas.cc:1518] Unable to register cuBLAS factory: Attempting to register factory for plugin cuBLAS when one has already been registered
/zhome/77/8/118225/.local/lib/python3.10/site-packages/numpy/core/getlimits.py:518: UserWarning: The value of the smallest subnormal for <class 'numpy.float32'> type is zero.
  setattr(self, word, getattr(machar, word).flat[0])
/zhome/77/8/118225/.local/lib/python3.10/site-packages/numpy/core/getlimits.py:89: UserWarning: The value of the smallest subnormal for <class 'numpy.float32'> type is zero.
  return self._float_to_str(self.smallest_subnormal)
2024-02-28 02:32:47.563376: W tensorflow/core/framework/op_kernel.cc:1827] INVALID_ARGUMENT: TypeError: `generator` yielded an element of shape (262144, 10) where an element of shape (262144, 8) was expected.
Traceback (most recent call last):

  File "/zhome/77/8/118225/.local/lib/python3.10/site-packages/tensorflow/python/ops/script_ops.py", line 270, in __call__
    ret = func(*args)

  File "/zhome/77/8/118225/.local/lib/python3.10/site-packages/tensorflow/python/autograph/impl/api.py", line 643, in wrapper
    return func(*args, **kwargs)

  File "/zhome/77/8/118225/.local/lib/python3.10/site-packages/tensorflow/python/data/ops/from_generator_op.py", line 235, in generator_py_func
    raise TypeError(

TypeError: `generator` yielded an element of shape (262144, 10) where an element of shape (262144, 8) was expected.


Traceback (most recent call last):
  File "/zhome/77/8/118225/Desktop/Projects/score_diffusion_mean/score_diffusion_mean/train_score.py", line 346, in <module>
    train_score()
  File "/zhome/77/8/118225/Desktop/Projects/score_diffusion_mean/score_diffusion_mean/train_score.py", line 324, in train_score
    train_s1(M=M,
  File "/zhome/77/8/118225/Desktop/Projects/score_diffusion_mean/score_diffusion_mean/jaxgeometry/statistics/score_matching/trainxt.py", line 94, in train_s1
    initial_params = model.init(jrandom.PRNGKey(seed), next(train_dataset)[:,:(2*N_dim+1)])
  File "/zhome/77/8/118225/.local/lib/python3.10/site-packages/tensorflow_datasets/core/dataset_utils.py", line 82, in _eager_dataset_iterator
    for elem in ds:
  File "/zhome/77/8/118225/.local/lib/python3.10/site-packages/tensorflow/python/data/ops/iterator_ops.py", line 809, in __next__
    return self._next_internal()
  File "/zhome/77/8/118225/.local/lib/python3.10/site-packages/tensorflow/python/data/ops/iterator_ops.py", line 772, in _next_internal
    ret = gen_dataset_ops.iterator_get_next(
  File "/zhome/77/8/118225/.local/lib/python3.10/site-packages/tensorflow/python/ops/gen_dataset_ops.py", line 3028, in iterator_get_next
    _ops.raise_from_not_ok_status(e, name)
  File "/zhome/77/8/118225/.local/lib/python3.10/site-packages/tensorflow/python/framework/ops.py", line 5888, in raise_from_not_ok_status
    raise core._status_to_exception(e) from None  # pylint: disable=protected-access
tensorflow.python.framework.errors_impl.InvalidArgumentError: {{function_node __wrapped__IteratorGetNext_output_types_1_device_/job:localhost/replica:0/task:0/device:CPU:0}} TypeError: `generator` yielded an element of shape (262144, 10) where an element of shape (262144, 8) was expected.
Traceback (most recent call last):

  File "/zhome/77/8/118225/.local/lib/python3.10/site-packages/tensorflow/python/ops/script_ops.py", line 270, in __call__
    ret = func(*args)

  File "/zhome/77/8/118225/.local/lib/python3.10/site-packages/tensorflow/python/autograph/impl/api.py", line 643, in wrapper
    return func(*args, **kwargs)

  File "/zhome/77/8/118225/.local/lib/python3.10/site-packages/tensorflow/python/data/ops/from_generator_op.py", line 235, in generator_py_func
    raise TypeError(

TypeError: `generator` yielded an element of shape (262144, 10) where an element of shape (262144, 8) was expected.


	 [[{{node PyFunc}}]] [Op:IteratorGetNext] name: 
terminate called without an active exception
/zhome/77/8/118225/.lsbatch/1708954003.20383758.shell: line 37: 15899 Aborted                 python3 train_score.py --manifold Cylinder --dim 2 --loss_type dsmvr --load_model 0 --T_sample 0 --t 0.1 --train_net s1 --max_T 1.0 --lr_rate 0.0002 --epochs 50000 --x_samples 64 --t_samples 256 --repeats 16 --samples_per_batch 32 --dt_steps 1000 --save_step 10 --seed 2712
